Workbook

Sheet اقرأني
A1: سجل حملات درب التسويقية
A3: الورقة | B3: ماذا فيها
A4: الحملات | B4: كل حملة في صف واحد بكل حقولها. هذه هي الورقة الأصل — عدّلي فيها.
A5: محطات الحملات | B5: صف لكل محطة داخل كل حملة، ومعها اسم المحطة ومدينتها وشريكها فيها.
A6: الشركاء | B6: الشركاء المشاركون بالعرض والسعرين والحالة. النوع والحالة قائمتان منسدلتان.
A7: أدوات الحملات | B7: جدول علامات: أي أداة استُخدمت في أي حملة.
A8: ملخّص الحملات | B8: مرتّب بحسب شهر الانطلاق، ويقرأ من ورقة «الحملات» — ما تغيّرينه هناك يظهر هنا.
A9: خطة واش واي | B9: اكتبي ميزانية كل حملة في العمود «ميزانية الحملة»، فيُحسب المصروف والباقي تلقائيًا، ويحمرّ الرقم لو تجاوز الميزانية.
A10: محطات درب | B10: محطات درب الـ١٢٧ بمستأجريها — مرشَّحة، للبحث عن كود أي محطة.
A11: القوائم | B11: الأدوات وأنواع الشركاء وحالاتهم — مرجع القوائم المنسدلة.
A13: كيف تفتحينها في درايف | B13: ارفعي الملف إلى Google Drive، ثم بزر الفأرة الأيمن ← فتح باستخدام ← Google Sheets، ثم ملف ← حفظ كـ Google Sheets.
A14: الصيغ | B14: تُنقل كما هي وتبقى حيّة بعد التحويل: الملخّص يقرأ من «الحملات»، وخطة واش واي تطرح من الإجمالي.

Sheet الحملات
A1: كود الحملة | B1: اسم الحملة | C1: الحملة الأساسية | D1: تاريخ البدء | E1: تاريخ الانتهاء | F1: المدة | G1: المحطات | H1: عدد المحطات | I1: الأدوات المستخدمة | J1: الهدف | K1: مؤشر القياس | L1: المستهدف | M1: الميزانية (ر.س) | N1: الشروط | O1: العرض المقترح | P1: عدد الشركاء | Q1: ملاحظات | R1: آخر تعديل
A2: CMP-2026-02 | B2: حملة سيارات النورية- افتتاح واش واي | D2: 2026-08-16 | E2: 2026-08-18 | F2: 3 أيام | G2: MK007 | H2: 1 | I2: فيديو تشويقي · فيديو عروض الحملة · فيديوهات المؤثّرين · حملة واتساب · توزيع كروت العرض · رمز QR للتفعيل | J2: مبيعات للمحطة | K2: عدد السيارات | L2: ١٠٠٠ سيارة | M2: 28000 | N2: تعبئة ب٦٠ ريال | P2: 1 | Q2: ٢٨ الف الباقي ٢٧٨٥٠ | R2: 2026-08-13
A3: CMP-2026-01 | B3: حملة فطور محطة العمرة | D3: 2026-08-19 | E3: 2026-09-15 | F3: 4 أسابيع | G3: MK007 | H3: 1 | I3: فيديو تشويقي · فيديو عروض الحملة · فيديوهات المؤثّرين · حملة واتساب · توزيع كروت العرض · لوحات المضخات · لافتات الطريق · رمز QR للتفعيل · النشر على منصات التواصل · تدريب عمال المحطة | J3: تفعيل الفترة الصباحية في محطة العمرة ورفع مبيعات الوحدات الغذائية بين ٠٥:٠٠ و١١:٠٠، وتحويل عملاء الوقود تحت المظلة إلى عملاء للوحدات. | K3: عمليات مسح QR الخاصة بالوحدة ÷ عدد سيارات الفترة الصباحية | L3: معدل التقاط ٥٪ من ٩٥٣ سيارة صباحًا | M3: 0 | N3: ١. يلتزم الشريك بتقديم العرض طوال مدة الحملة وبالسعر المتفق عليه. ٢. يلتزم الشريك بالفتح في الموعد المحدّد للحملة وبتوفير الكمية اليومية المتفق عليها. ٣. تتحمّل درب تنفيذ المحتوى والتصوير والنشر والتوزيع الميداني داخل المحطة. ٤. لا تتحمّل درب قيمة العرض ولا تكلفة التعاقد مع المؤثّرين. ٥. يُفعَّل العرض بمسح رمز QR، ولا يُجمع مع أي عرض آخر. ٦. يُرسل تقرير القياس أسبوعيًا، وتُراجع العروض في نهاية الأسبوع الثالث. ٧. لأي طرف إنهاء المشاركة بإشعار مكتوب قبل سبعة أيام. | O3: وجبة فطور بسعر خاص، أو مشروب مجاني مع أي فطور، مقابل تعبئة وقود بقيمة يحدّدها الاتفاق، ويُفعَّل بمسح رمز QR على كرت الفطور بين ٠٥:٠٠ و١١:٠٠. | P3: 0 | R3: 2026-08-12
A4: CMP-2026-03 | B4: حملة السيارات- محطات التشغيل ال٨+3 محطات | D4: 2026-08-23 | E4: 2026-08-28 | F4: 6 أيام | G4: RY075 · MK023 · MK017 · MK035 · MK099 · MK015 · JA069 | H4: 7 | I4: فيديو تشويقي · فيديو عروض الحملة · فيديوهات المؤثّرين · حملة واتساب · توزيع كروت العرض · رمز QR للتفعيل | J4: زيادة المبيعات | M4: 19000 | N4: تعبئة المتوسط من كل محطة بالرجوع للتحليلات | P4: 4 | R4: 2026-08-16
A5: CMP-2026-04 | B5: حملة الكافيهات في الخمس محطات | D5: 2026-08-30 | E5: 2026-09-04 | F5: 6 أيام | G5: MK019 · MK002 · MK017 · MK023 | H5: 4 | I5: فيديو تشويقي · فيديو عروض الحملة · فيديوهات المؤثّرين · حملة واتساب · توزيع كروت العرض · رمز QR للتفعيل | J5: براندغ | M5: 0 | P5: 4 | R5: 2026-08-12
A6: CMP-2026-05 | B6: حملة اليوم الوطني في مكة(واش واي) | D6: 2026-09-17 | E6: 2026-09-19 | F6: 3 أيام | G6: MK007 | H6: 1 | I6: فيديو تشويقي · فيديو عروض الحملة · فيديوهات المؤثّرين · حملة واتساب · توزيع كروت العرض | J6: رفع المبيعات | L6: ١٠٠٠ سيارة | M6: 28000 | P6: 1 | Q6: تكلفة الحملة ٢٨٠٠٠ الباقي ٧٥٠٠٠ | R6: 2026-08-13
A7: CMP-2026-07 | B7: حملة شهر اكتوبر | D7: 2026-10-01 | E7: 2026-10-01 | F7: 1 أيام | H7: 0 | J7: حملة ضمن خطة واش واي | M7: 19000 | P7: 1 | R7: 2026-08-13
A8: CMP-2026-06 | B8: الجمعة البرتقالية | D8: 2026-11-15 | E8: 2026-11-15 | F8: 1 أيام | H8: 0 | J8: حملة ضمن خطة واش واي | M8: 19000 | P8: 1 | R8: 2026-08-13
A9: CMP-2026-08 | B9: عروض نهاية العام - او العام الجديدي | D9: 2026-12-01 | E9: 2026-12-01 | F9: 1 أيام | H9: 0 | J9: حملة ضمن خطة واش واي | M9: 19000 | P9: 1 | R9: 2026-08-13

Sheet محطات الحملات
A1: كود الحملة | B1: اسم الحملة | C1: كود المحطة | D1: اسم المحطة | E1: المدينة | F1: الشريك في هذه المحطة
A2: CMP-2026-02 | B2: حملة سيارات النورية- افتتاح واش واي | C2: MK007 | D2: النوارية | E2: مكة
A3: CMP-2026-01 | B3: حملة فطور محطة العمرة | C3: MK007 | D3: النوارية | E3: مكة
A4: CMP-2026-03 | B4: حملة السيارات- محطات التشغيل ال٨+3 محطات | C4: RY075 | D4: الدايري الشمالي | E4: الرياض | F4: واش واي
A5: CMP-2026-03 | B5: حملة السيارات- محطات التشغيل ال٨+3 محطات | C5: MK023 | D5: بن درويش | E5: مكة | F5: درب الصيانة غسيل وبنشر
A6: CMP-2026-03 | B6: حملة السيارات- محطات التشغيل ال٨+3 محطات | C6: MK017 | D6: عرفات الشوقية | E6: مكة | F6: مغسلة water wash
A7: CMP-2026-03 | B7: حملة السيارات- محطات التشغيل ال٨+3 محطات | C7: MK035 | D7: الجمعية الوسام( طريق الملك فهد) | E7: الطائف
A8: CMP-2026-03 | B8: حملة السيارات- محطات التشغيل ال٨+3 محطات | C8: MK099 | D8: البيعه | E8: الطائف | F8: ترويشة غسيل سيارات
A9: CMP-2026-03 | B9: حملة السيارات- محطات التشغيل ال٨+3 محطات | C9: MK015 | D9: النسيم | E9: جدة
A10: CMP-2026-03 | B10: حملة السيارات- محطات التشغيل ال٨+3 محطات | C10: JA069 | D10: كورنيش جيزان | E10: جازان
A11: CMP-2026-04 | B11: حملة الكافيهات في الخمس محطات | C11: MK019 | D11: الشرايع | E11: مكة | F11: بون
A12: CMP-2026-04 | B12: حملة الكافيهات في الخمس محطات | C12: MK002 | D12: المعيصم | E12: مكة | F12: بون
A13: CMP-2026-04 | B13: حملة الكافيهات في الخمس محطات | C13: MK017 | D13: عرفات الشوقية | E13: مكة | F13: بون
A14: CMP-2026-04 | B14: حملة الكافيهات في الخمس محطات | C14: MK023 | D14: بن درويش | E14: مكة | F14: بون
A15: CMP-2026-05 | B15: حملة اليوم الوطني في مكة(واش واي) | C15: MK007 | D15: النوارية | E15: مكة | F15: واش واي

Sheet الشركاء
A1: كود الحملة | B1: اسم الحملة | C1: الشريك | D1: النوع | E1: كود المحطة | F1: اسم المحطة | G1: فكرة العرض | H1: السعر الاعتيادي | I1: سعر الحملة | J1: الحالة
A2: CMP-2026-02 | B2: حملة سيارات النورية- افتتاح واش واي | C2: واش واي | G2: غسلة خارجية ب١٠ ريال | H2: ١ | J2: بانتظار الرد
A3: CMP-2026-03 | B3: حملة السيارات- محطات التشغيل ال٨+3 محطات | C3: واش واي | E3: RY075 | F3: الدايري الشمالي | I3: ١٥ | J3: بانتظار الرد
A4: CMP-2026-03 | B4: حملة السيارات- محطات التشغيل ال٨+3 محطات | C4: مغسلة water wash | E4: MK017 | F4: عرفات الشوقية | I4: ١٠ | J4: بانتظار الرد
A5: CMP-2026-03 | B5: حملة السيارات- محطات التشغيل ال٨+3 محطات | C5: ترويشة غسيل سيارات | E5: MK099 | F5: البيعه | I5: ١٠ | J5: بانتظار الرد
A6: CMP-2026-03 | B6: حملة السيارات- محطات التشغيل ال٨+3 محطات | C6: درب الصيانة غسيل وبنشر | E6: MK023 | F6: بن درويش | I6: 10 | J6: بانتظار الرد
A7: CMP-2026-04 | B7: حملة الكافيهات في الخمس محطات | C7: بون | E7: MK019 | F7: الشرايع | G7: كوب قهوة | I7: ٥ | J7: بانتظار الرد
A8: CMP-2026-04 | B8: حملة الكافيهات في الخمس محطات | C8: بون | E8: MK002 | F8: المعيصم | G8: كوب قهوة | I8: ٥ | J8: بانتظار الرد
A9: CMP-2026-04 | B9: حملة الكافيهات في الخمس محطات | C9: بون | E9: MK017 | F9: عرفات الشوقية | G9: كوب قهوة | I9: ٥ | J9: بانتظار الرد
A10: CMP-2026-04 | B10: حملة الكافيهات في الخمس محطات | C10: بون | E10: MK023 | F10: بن درويش | G10: كوب قهوة | I10: ٥ | J10: بانتظار الرد
A11: CMP-2026-05 | B11: حملة اليوم الوطني في مكة(واش واي) | C11: واش واي | E11: MK007 | F11: النوارية | G11: عبي فل وغسل بريال | I11: ١ | J11: بانتظار الرد
A12: CMP-2026-07 | B12: حملة شهر اكتوبر | C12: واش واي | G12: ١٠ | J12: بانتظار الرد
A13: CMP-2026-06 | B13: الجمعة البرتقالية | C13: واش واي | G13: غسلة ب١٠ | J13: بانتظار الرد
A14: CMP-2026-08 | B14: عروض نهاية العام - او العام الجديدي | C14: واش واي | G14: ١٠ | J14: بانتظار الرد

Sheet أدوات الحملات
A1: كود الحملة | B1: اسم الحملة | C1: فيديو تشويقي | D1: فيديو عروض الحملة | E1: فيديوهات المؤثّرين | F1: حملة واتساب | G1: توزيع كروت العرض | H1: لوحات المضخات | I1: لافتات الطريق | J1: رمز QR للتفعيل | K1: بروشور مطبوع | L1: النشر على منصات التواصل | M1: إعلانات مدفوعة | N1: تدريب عمال المحطة
A2: CMP-2026-02 | B2: حملة سيارات النورية- افتتاح واش واي | C2: ✓ | D2: ✓ | E2: ✓ | F2: ✓ | G2: ✓ | J2: ✓
A3: CMP-2026-01 | B3: حملة فطور محطة العمرة | C3: ✓ | D3: ✓ | E3: ✓ | F3: ✓ | G3: ✓ | H3: ✓ | I3: ✓ | J3: ✓ | L3: ✓ | N3: ✓
A4: CMP-2026-03 | B4: حملة السيارات- محطات التشغيل ال٨+3 محطات | C4: ✓ | D4: ✓ | E4: ✓ | F4: ✓ | G4: ✓ | J4: ✓
A5: CMP-2026-04 | B5: حملة الكافيهات في الخمس محطات | C5: ✓ | D5: ✓ | E5: ✓ | F5: ✓ | G5: ✓ | J5: ✓
A6: CMP-2026-05 | B6: حملة اليوم الوطني في مكة(واش واي) | C6: ✓ | D6: ✓ | E6: ✓ | F6: ✓ | G6: ✓
A7: CMP-2026-07 | B7: حملة شهر اكتوبر
A8: CMP-2026-06 | B8: الجمعة البرتقالية
A9: CMP-2026-08 | B9: عروض نهاية العام - او العام الجديدي

Sheet ملخّص الحملات
A1: الشهر | B1: كود الحملة | C1: اسم الحملة | D1: تاريخ البدء | E1: تاريخ الانتهاء | F1: المدة | G1: المحطات | H1: الشركاء | I1: الميزانية (ر.س) | J1: الهدف
A2: أغسطس 2026 | B2: ='الحملات'!A2 | C2: ='الحملات'!B2 | D2: ='الحملات'!D2 | E2: ='الحملات'!E2 | F2: ='الحملات'!F2 | G2: ='الحملات'!H2 | H2: ='الحملات'!P2 | I2: ='الحملات'!M2 | J2: ='الحملات'!J2
A3: أغسطس 2026 | B3: ='الحملات'!A3 | C3: ='الحملات'!B3 | D3: ='الحملات'!D3 | E3: ='الحملات'!E3 | F3: ='الحملات'!F3 | G3: ='الحملات'!H3 | H3: ='الحملات'!P3 | I3: ='الحملات'!M3 | J3: ='الحملات'!J3
A4: أغسطس 2026 | B4: ='الحملات'!A4 | C4: ='الحملات'!B4 | D4: ='الحملات'!D4 | E4: ='الحملات'!E4 | F4: ='الحملات'!F4 | G4: ='الحملات'!H4 | H4: ='الحملات'!P4 | I4: ='الحملات'!M4 | J4: ='الحملات'!J4
A5: أغسطس 2026 | B5: ='الحملات'!A5 | C5: ='الحملات'!B5 | D5: ='الحملات'!D5 | E5: ='الحملات'!E5 | F5: ='الحملات'!F5 | G5: ='الحملات'!H5 | H5: ='الحملات'!P5 | I5: ='الحملات'!M5 | J5: ='الحملات'!J5
A6: سبتمبر 2026 | B6: ='الحملات'!A6 | C6: ='الحملات'!B6 | D6: ='الحملات'!D6 | E6: ='الحملات'!E6 | F6: ='الحملات'!F6 | G6: ='الحملات'!H6 | H6: ='الحملات'!P6 | I6: ='الحملات'!M6 | J6: ='الحملات'!J6
A7: أكتوبر 2026 | B7: ='الحملات'!A7 | C7: ='الحملات'!B7 | D7: ='الحملات'!D7 | E7: ='الحملات'!E7 | F7: ='الحملات'!F7 | G7: ='الحملات'!H7 | H7: ='الحملات'!P7 | I7: ='الحملات'!M7 | J7: ='الحملات'!J7
A8: نوفمبر 2026 | B8: ='الحملات'!A8 | C8: ='الحملات'!B8 | D8: ='الحملات'!D8 | E8: ='الحملات'!E8 | F8: ='الحملات'!F8 | G8: ='الحملات'!H8 | H8: ='الحملات'!P8 | I8: ='الحملات'!M8 | J8: ='الحملات'!J8
A9: ديسمبر 2026 | B9: ='الحملات'!A9 | C9: ='الحملات'!B9 | D9: ='الحملات'!D9 | E9: ='الحملات'!E9 | F9: ='الحملات'!F9 | G9: ='الحملات'!H9 | H9: ='الحملات'!P9 | I9: ='الحملات'!M9 | J9: ='الحملات'!J9
A11: الإجمالي | G11: =SUM(G2:G9) | H11: =SUM(H2:H9) | I11: =SUM(I2:I9)

Sheet خطة واش واي
A1: كود الحملة | B1: اسم الحملة | C1: تاريخ البدء | D1: المحطات | E1: ميزانية الحملة (ر.س) | F1: المصروف حتى هنا | G1: الباقي من الميزانية | I1: إجمالي الميزانية | J1: 150000
A2: CMP-2026-02 | B2: حملة سيارات النورية- افتتاح واش واي | C2: 2026-08-16 | D2: MK007 | E2: 28000 | F2: =SUM($E$2:E2) | G2: =$J$1-F2 | I2: المدة (أشهر) | J2: 5
A3: CMP-2026-03 | B3: حملة السيارات- محطات التشغيل ال٨+3 محطات | C3: 2026-08-23 | D3: RY075 · MK023 · MK017 · MK035 · MK099 · MK015 · JA069 | E3: 19000 | F3: =SUM($E$2:E3) | G3: =$J$1-F3 | I3: الشريك | J3: واش واي
A4: CMP-2026-05 | B4: حملة اليوم الوطني في مكة(واش واي) | C4: 2026-09-17 | D4: MK007 | E4: 28000 | F4: =SUM($E$2:E4) | G4: =$J$1-F4 | I4: المصروف | J4: =SUM(E2:E7)
A5: CMP-2026-07 | B5: حملة شهر اكتوبر | C5: 2026-10-01 | E5: 19000 | F5: =SUM($E$2:E5) | G5: =$J$1-F5 | I5: الباقي | J5: =J1-J4
A6: CMP-2026-06 | B6: الجمعة البرتقالية | C6: 2026-11-15 | E6: 19000 | F6: =SUM($E$2:E6) | G6: =$J$1-F6 | I6: حدّ الشهر | J6: =IF(J2>0,J1/J2,0)
A7: CMP-2026-08 | B7: عروض نهاية العام - او العام الجديدي | C7: 2026-12-01 | E7: 19000 | F7: =SUM($E$2:E7) | G7: =$J$1-F7

Sheet محطات درب
A1: كود المحطة | B1: اسم المحطة | C1: المدينة | D1: الحالة | E1: التشغيل | F1: المستأجرون | G1: وحدات | H1: مؤجّرة | I1: شاغرة
A2: AS081 | B2: خميس مشيط العزيزيه | C2: خميس مشيط | D2: تعمل | E2: امتياز | F2: بترومين · KRO كافيه | G2: 6 | H2: 3 | I2: 3
A3: AS085 | B3: خيبر بيشة | C3: عسير | D3: تعمل | E3: امتياز | G3: 12 | H3: 0 | I3: 12
A4: AS124 | B4: الصفاء | C4: عسير | D4: تحت التنفيذ | E4: مُدارة من درب
A5: AS141 | B5: الأمير سلطان | C5: عسير | D5: تحت التنفيذ | E5: مُدارة من درب
A6: AS153 | B6: مدخل محايل | C6: عسير | D6: تحت التنفيذ | E6: مُدارة من درب
A7: AS192 | B7: محطه الرؤيا | C7: عسير | D7: تحت التنفيذ | E7: مُدارة من درب
A8: AS197 | B8: سوق الاشواق | C8: خميس مشيط | D8: تحت التنفيذ | E8: مُدارة من درب
A9: AS271 | B9: مسارات درب عقبة شعار | C9: عسير | D9: تعمل | E9: امتياز | F9: بارنز كافيه
A10: AS286 | B10: صناعية محائل | C10: محايل عسير | D10: تحت التنفيذ | E10: مُدارة من درب
A11: BH050 | B11: الاطاولة | C11: الباحة | D11: تحت التنفيذ | E11: مُدارة من درب
A12: BH065 | B12: النزهه | C12: الباحة | D12: تعمل | E12: امتياز | F12: بترومين · كودو · دوز كافيه · ودق ماركت · صراف بنك الاهلي
A13: BH126 | B13: محطة الحميدان | C13: الباحة | D13: تحت التنفيذ | E13: مُدارة من درب
A14: EB102 | B14: طريق احد | C14: القطيف | D14: تعمل | E14: امتياز | G14: 2 | H14: 0 | I14: 2
A15: EP051 | B15: كورنيش الخبر | C15: الخبر | D15: تعمل | E15: مُدارة من درب
A16: EP074 | B16: حي الورود | C16: حفر الباطن | D16: تحت التنفيذ | E16: مُدارة من درب
A17: EP102 | B17: شارع أحد تاروت-القطيف | C17: الشرقية | D17: تعمل | E17: امتياز | F17: تموينات الذاهب · صراف بنك الجزيرة
A18: EP132 | B18: الذيبة | C18: حفر الباطن | D18: تحت التنفيذ | E18: امتياز | G18: 5 | H18: 4 | I18: 1
A19: EP133 | B19: طريق الملك عبدالله | C19: حفر الباطن | D19: تحت التنفيذ | E19: امتياز
A20: EP134 | B20: حفر الباطن - الواحة | C20: الشرقية | D20: تحت التنفيذ | E20: امتياز | G20: 8 | H20: 7 | I20: 1
A21: HA043 | B21: العريفي | C21: حائل | D21: تعمل | E21: مُدارة من درب | F21: مغسلة طمس · مركز التقدم الذهبي خدمات سيارات · DOB كافيه · بوبايز · بارنز كافيه · تموينات شموع
A22: HA050 | B22: مطار حائل | C22: حائل | D22: تحت التنفيذ | E22: امتياز
A23: HA052 | B23: الأمير سعود | C23: حائل | D23: تحت التنفيذ | E23: امتياز | G23: 10 | H23: 5 | I23: 5
A24: JA041 | B24: احد المسارحة - القسوم | C24: جازان | D24: تحت التنفيذ | E24: مُدارة من درب
A25: JA053 | B25: خبت نخلان(الملك عبد العزيز)-جيزان | C25: جازان | D25: تعمل | E25: مُدارة من درب | F25: سوبر ماركت مترو مارت
A26: JA056 | B26: الروابي-المودة | C26: جازان | D26: تعمل | E26: مُدارة من درب
A27: JA059 | B27: طريق الملك فهد جازان | C27: جازان | D27: تحت التنفيذ | E27: مُدارة من درب
A28: JA060 | B28: صناعية صامطه | C28: جازان | D28: تعمل | E28: مُدارة من درب | F28: اويل زون · مطعم لهب الطعام
A29: JA061 | B29: طريق صبيا | C29: جازان | D29: تعمل | E29: مُدارة من درب | F29: البترول الذهبي · كوفي بلاك اند وايت · دوز كافيه · Cove كافيه · فريش واي
A30: JA069 | B30: كورنيش جيزان | C30: جازان | D30: تعمل | E30: مُدارة من درب | F30: مرسى مطروح · كوفي لوتسو سويت آند ستوري · ماهو كافيه -المذاق المغربي · كوفي 24 · مزاج المغربي - · فرست مارت
A31: JA070 | B31: محطة الظبية | C31: جازان | D31: تحت التنفيذ | E31: امتياز | G31: 31 | H31: 1 | I31: 30
A32: JA092 | B32: احد المسارحة - البلدية | C32: جازان | D32: تعمل | E32: امتياز
A33: JA094 | B33: الكربوس (محطة الزهور ) | C33: جازان | D33: تحت التنفيذ | E33: مُدارة من درب
A34: JA155 | B34: محطة بترو بارك | C34: جازان | D34: تحت التنفيذ | E34: امتياز
A35: JA156 | B35: العيدابي | C35: جازان | D35: تعمل | E35: امتياز
A36: JA188 | B36: محطة طريق الملك عبدالعزيز بيش | C36: بيشة | D36: تحت التنفيذ | E36: مُدارة من درب
A37: JA227 | B37: العارضة | C37: جازان | D37: تعمل | E37: مُدارة من درب | F37: البترول الذهبي · صراف بنك البلاد | G37: 7 | H37: 0 | I37: 7
A38: JA256 | B38: الفطيحة | C38: جازان | D38: تعمل | E38: امتياز
A39: JA272 | B39: الفيصلية | C39: جازان | D39: تعمل | E39: امتياز
A40: JA302 | B40: جزيرة فرسان - | C40: جازان | D40: تعمل | E40: امتياز
...

Sheet القوائم
A1: الأدوات | B1: أنواع الشركاء | C1: حالات الشريك
A2: فيديو تشويقي | B2: مطعم | C2: بانتظار الرد
A3: فيديو عروض الحملة | B3: مقهى | C3: موافق
A4: فيديوهات المؤثّرين | B4: مخبز أو حلويات | C4: معتذر
A5: حملة واتساب | B5: عصائر | C5: قيد التفاوض
A6: توزيع كروت العرض | B6: سوبرماركت
A7: لوحات المضخات | B7: خدمات سيارات
A8: لافتات الطريق | B8: مغسلة سيارات
A9: رمز QR للتفعيل | B9: صراف أو بنك
A10: بروشور مطبوع | B10: تطبيق توصيل
A11: النشر على منصات التواصل | B11: علامة تجارية راعية
A12: إعلانات مدفوعة | B12: اتصالات
A13: تدريب عمال المحطة | B13: تأمين
B14: جهة حكومية
B15: أخرى
